<?xml version="1.0" encoding="UTF-8"?>
<!-- Generated by org.testng.reporters.JUnitReportReporter -->
<testsuite hostname="DESKTOP-B6NN9JJ" failures="0" tests="4" name="leetCode_Practice.LC_217_ContainsDuplicate" time="0.045" errors="1" timestamp="2023-09-10T16:18:39 IST" skipped="0">
  <testcase classname="leetCode_Practice.LC_217_ContainsDuplicate" name="validData" time="0.006"/>
  <testcase classname="leetCode_Practice.LC_217_ContainsDuplicate" name="invalidData" time="0.003">
    <error message="Index 5 out of bounds for length 5" type="java.lang.ArrayIndexOutOfBoundsException">
      <![CDATA[java.lang.ArrayIndexOutOfBoundsException: Index 5 out of bounds for length 5
at leetCode_Practice.LC_217_ContainsDuplicate.containsDuplicate(LC_217_ContainsDuplicate.java:52)
at leetCode_Practice.LC_217_ContainsDuplicate.invalidData(LC_217_ContainsDuplicate.java:36)
at java.base/jdk.internal.reflect.DirectMethodHandleAccessor.invoke(DirectMethodHandleAccessor.java:104)
at java.base/java.lang.reflect.Method.invoke(Method.java:578)
at org.testng.internal.invokers.MethodInvocationHelper.invokeMethod(MethodInvocationHelper.java:139)
at org.testng.internal.invokers.TestInvoker.invokeMethod(TestInvoker.java:664)
at org.testng.internal.invokers.TestInvoker.invokeTestMethod(TestInvoker.java:227)
at org.testng.internal.invokers.MethodRunner.runInSequence(MethodRunner.java:50)
at org.testng.internal.invokers.TestInvoker$MethodInvocationAgent.invoke(TestInvoker.java:957)
at org.testng.internal.invokers.TestInvoker.invokeTestMethods(TestInvoker.java:200)
at org.testng.internal.invokers.TestMethodWorker.invokeTestMethods(TestMethodWorker.java:148)
at org.testng.internal.invokers.TestMethodWorker.run(TestMethodWorker.java:128)
at java.base/java.util.ArrayList.forEach(ArrayList.java:1511)
at org.testng.TestRunner.privateRun(TestRunner.java:848)
at org.testng.TestRunner.run(TestRunner.java:621)
at org.testng.SuiteRunner.runTest(SuiteRunner.java:443)
at org.testng.SuiteRunner.runSequentially(SuiteRunner.java:437)
at org.testng.SuiteRunner.privateRun(SuiteRunner.java:397)
at org.testng.SuiteRunner.run(SuiteRunner.java:336)
at org.testng.SuiteRunnerWorker.runSuite(SuiteRunnerWorker.java:52)
at org.testng.SuiteRunnerWorker.run(SuiteRunnerWorker.java:95)
at org.testng.TestNG.runSuitesSequentially(TestNG.java:1280)
at org.testng.TestNG.runSuitesLocally(TestNG.java:1200)
at org.testng.TestNG.runSuites(TestNG.java:1114)
at org.testng.TestNG.run(TestNG.java:1082)
at org.testng.remote.AbstractRemoteTestNG.run(AbstractRemoteTestNG.java:115)
at org.testng.remote.RemoteTestNG.initAndRun(RemoteTestNG.java:251)
at org.testng.remote.RemoteTestNG.main(RemoteTestNG.java:77)
]]>
    </error>
  </testcase> <!-- invalidData -->
  <testcase classname="leetCode_Practice.LC_217_ContainsDuplicate" name="edgeData" time="0.032"/>
  <testcase classname="leetCode_Practice.LC_217_ContainsDuplicate" name="test" time="0.004"/>
</testsuite> <!-- leetCode_Practice.LC_217_ContainsDuplicate -->
